Workbook

Sheet How to use
A1: ReCOGnAIze · /parkwayshenton: Malay (Bahasa Melayu) translation review
A2: Every visitor-facing string in the Parkway Shenton flow, in English and Malay, in the order a visitor meets them. Taken from the app's copy files at commit 9efce8d.
A4: What to do
A5: 1. Read | B5: On the Translations tab, read each row's English, then the current Malay. The English is the source; the Malay is what the app shows today.
A6: 2. Mark a status | B6: In the Status column, pick OK, Change needed or Question from the dropdown.
A7: 3. Suggest a fix | B7: For Change needed, type the full corrected text in Suggested text (the whole string, not just the changed word).
A8: 4. Comment | B8: Use Comments for anything else: a question, a note on tone, a term to use consistently.
A9: Only edit | B9: The yellow columns (Status, Suggested text, Comments). Please don't add, delete or reorder columns: your answers are matched back to the app by the ID in column A.
A11: Example of a filled-in row (illustration only, not a real finding)
A12: English | B12: Get started for free
A13: Malay (current) | B13: Mula secara percuma
A14: Status | B14: Change needed
A15: Suggested text | B15: Mulakan secara percuma
A16: Comments | B16: "Mulakan" reads more naturally as a call to action.
A18: Reading the rows
A19: {placeholders} | B19: Text in curly brackets, such as {name}, {percentile} or {ageLabel}, is replaced by a live value. Keep it exactly as written, but move it wherever it reads naturally.
A20: Grey rows | B20: "Assembled preview" rows show a sentence that the screen builds from several rows (for example a headline with one word in italics, or a clause with a link in the middle). Use the preview to judge how the sentence reads; put corrections on the individual rows beneath it.
A21: Fragments | B21: Rows marked "Fragment" are pieces of one sentence. Spaces at the start or end are part of the text and matter.
A22: Orange cells | B22: Text that is hardcoded in English and stays English in every language (for example a journal title, or a game screen with no translation yet). Mark it Change needed if it should be translated.
A23: Red rows (legal) | B23: IHH Healthcare Singapore's consent clauses. The English is IHH's own legal wording; the Malay is our in-house translation, not IHH's, and must say exactly what the English says, no more and no less.
A24: Shown when | B24: Blank means the text is always shown. The report comes in four versions (under 40 / 40 and over × fast / slower result); report rows name the versions they appear in.
A25: Screen readers | B25: Rows marked "screen readers" are not printed on screen but are read aloud to visually impaired visitors. Please still translate them.
A26: Screen 9 | B26: The "full picture" page (/parkwayshenton/report-full) is translated, but nothing in the flow links to it at the moment. Review it only if time allows.
A28: Tabs
A29: Translations | B29: The flow, screen by screen: landing, what happens next, game intro, tutorial and game, game complete, quiz, loading, report, and the optional unlinked page.
A30: Progress | B30: Counts per screen, filled in automatically from your statuses.
A32: Not in this sheet
A33: Result email | B33: The email with the visitor's result is sent in English whatever language they picked, by design, so it isn't here.
A34: Brand & proper names | B34: ReCOGnAIze, Gray Matter Solutions, IHH Healthcare Singapore, BrainScan and the press logos are shown as they are and are not listed separately.

Sheet Progress
A1: Review progress by screen
A2: Counts update as statuses are filled in. Preview (grey) rows are not counted.
A4: Screen | B4: Strings | C4: reviewed | D4: OK | E4: change needed | F4: question | G4: % reviewed
A5: 1 · Landing (/parkwayshenton) | B5: =COUNTIFS(Translations!$B$5:$B$487,$A5,Translations!$A$5:$A$487,">0") -> 44 | C5: =D5+E5+F5 -> 0 | D5: =COUNTIFS(Translations!$B$5:$B$487,$A5,Translations!$A$5:$A$487,">0",Translations!$I$5:$I$487,"OK") -> 0 | E5: =COUNTIFS(Translations!$B$5:$B$487,$A5,Translations!$A$5:$A$487,">0",Translations!$I$5:$I$487,"Change needed") -> 0 | F5: =COUNTIFS(Translations!$B$5:$B$487,$A5,Translations!$A$5:$A$487,">0",Translations!$I$5:$I$487,"Question") -> 0 | G5: =IF($B5=0,0,C5/$B5) -> 0
A6: 2 · What happens next (/parkwayshenton/ready) | B6: =COUNTIFS(Translations!$B$5:$B$487,$A6,Translations!$A$5:$A$487,">0") -> 13 | C6: =D6+E6+F6 -> 0 | D6: =COUNTIFS(Translations!$B$5:$B$487,$A6,Translations!$A$5:$A$487,">0",Translations!$I$5:$I$487,"OK") -> 0 | E6: =COUNTIFS(Translations!$B$5:$B$487,$A6,Translations!$A$5:$A$487,">0",Translations!$I$5:$I$487,"Change needed") -> 0 | F6: =COUNTIFS(Translations!$B$5:$B$487,$A6,Translations!$A$5:$A$487,">0",Translations!$I$5:$I$487,"Question") -> 0 | G6: =IF($B6=0,0,C6/$B6) -> 0
A7: 3 · Game intro (/parkwayshenton/challenge) | B7: =COUNTIFS(Translations!$B$5:$B$487,$A7,Translations!$A$5:$A$487,">0") -> 8 | C7: =D7+E7+F7 -> 0 | D7: =COUNTIFS(Translations!$B$5:$B$487,$A7,Translations!$A$5:$A$487,">0",Translations!$I$5:$I$487,"OK") -> 0 | E7: =COUNTIFS(Translations!$B$5:$B$487,$A7,Translations!$A$5:$A$487,">0",Translations!$I$5:$I$487,"Change needed") -> 0 | F7: =COUNTIFS(Translations!$B$5:$B$487,$A7,Translations!$A$5:$A$487,">0",Translations!$I$5:$I$487,"Question") -> 0 | G7: =IF($B7=0,0,C7/$B7) -> 0
A8: 4 · Tutorial & game (/symbol-matching) | B8: =COUNTIFS(Translations!$B$5:$B$487,$A8,Translations!$A$5:$A$487,">0") -> 28 | C8: =D8+E8+F8 -> 0 | D8: =COUNTIFS(Translations!$B$5:$B$487,$A8,Translations!$A$5:$A$487,">0",Translations!$I$5:$I$487,"OK") -> 0 | E8: =COUNTIFS(Translations!$B$5:$B$487,$A8,Translations!$A$5:$A$487,">0",Translations!$I$5:$I$487,"Change needed") -> 0 | F8: =COUNTIFS(Translations!$B$5:$B$487,$A8,Translations!$A$5:$A$487,">0",Translations!$I$5:$I$487,"Question") -> 0 | G8: =IF($B8=0,0,C8/$B8) -> 0
A9: 5 · Game complete (/parkwayshenton/game-complete) | B9: =COUNTIFS(Translations!$B$5:$B$487,$A9,Translations!$A$5:$A$487,">0") -> 7 | C9: =D9+E9+F9 -> 0 | D9: =COUNTIFS(Translations!$B$5:$B$487,$A9,Translations!$A$5:$A$487,">0",Translations!$I$5:$I$487,"OK") -> 0 | E9: =COUNTIFS(Translations!$B$5:$B$487,$A9,Translations!$A$5:$A$487,">0",Translations!$I$5:$I$487,"Change needed") -> 0 | F9: =COUNTIFS(Translations!$B$5:$B$487,$A9,Translations!$A$5:$A$487,">0",Translations!$I$5:$I$487,"Question") -> 0 | G9: =IF($B9=0,0,C9/$B9) -> 0
A10: 6 · Brain health quiz (/parkwayshenton/quiz) | B10: =COUNTIFS(Translations!$B$5:$B$487,$A10,Translations!$A$5:$A$487,">0") -> 114 | C10: =D10+E10+F10 -> 0 | D10: =COUNTIFS(Translations!$B$5:$B$487,$A10,Translations!$A$5:$A$487,">0",Translations!$I$5:$I$487,"OK") -> 0 | E10: =COUNTIFS(Translations!$B$5:$B$487,$A10,Translations!$A$5:$A$487,">0",Translations!$I$5:$I$487,"Change needed") -> 0 | F10: =COUNTIFS(Translations!$B$5:$B$487,$A10,Translations!$A$5:$A$487,">0",Translations!$I$5:$I$487,"Question") -> 0 | G10: =IF($B10=0,0,C10/$B10) -> 0
A11: 7 · Building your profile (/parkwayshenton/loading) | B11: =COUNTIFS(Translations!$B$5:$B$487,$A11,Translations!$A$5:$A$487,">0") -> 9 | C11: =D11+E11+F11 -> 0 | D11: =COUNTIFS(Translations!$B$5:$B$487,$A11,Translations!$A$5:$A$487,">0",Translations!$I$5:$I$487,"OK") -> 0 | E11: =COUNTIFS(Translations!$B$5:$B$487,$A11,Translations!$A$5:$A$487,">0",Translations!$I$5:$I$487,"Change needed") -> 0 | F11: =COUNTIFS(Translations!$B$5:$B$487,$A11,Translations!$A$5:$A$487,">0",Translations!$I$5:$I$487,"Question") -> 0 | G11: =IF($B11=0,0,C11/$B11) -> 0
A12: 8 · Report (/parkwayshenton/report) | B12: =COUNTIFS(Translations!$B$5:$B$487,$A12,Translations!$A$5:$A$487,">0") -> 203 | C12: =D12+E12+F12 -> 0 | D12: =COUNTIFS(Translations!$B$5:$B$487,$A12,Translations!$A$5:$A$487,">0",Translations!$I$5:$I$487,"OK") -> 0 | E12: =COUNTIFS(Translations!$B$5:$B$487,$A12,Translations!$A$5:$A$487,">0",Translations!$I$5:$I$487,"Change needed") -> 0 | F12: =COUNTIFS(Translations!$B$5:$B$487,$A12,Translations!$A$5:$A$487,">0",Translations!$I$5:$I$487,"Question") -> 0 | G12: =IF($B12=0,0,C12/$B12) -> 0
A13: 9 · Not linked (optional): /parkwayshenton/report-full | B13: =COUNTIFS(Translations!$B$5:$B$487,$A13,Translations!$A$5:$A$487,">0") -> 37 | C13: =D13+E13+F13 -> 0 | D13: =COUNTIFS(Translations!$B$5:$B$487,$A13,Translations!$A$5:$A$487,">0",Translations!$I$5:$I$487,"OK") -> 0 | E13: =COUNTIFS(Translations!$B$5:$B$487,$A13,Translations!$A$5:$A$487,">0",Translations!$I$5:$I$487,"Change needed") -> 0 | F13: =COUNTIFS(Translations!$B$5:$B$487,$A13,Translations!$A$5:$A$487,">0",Translations!$I$5:$I$487,"Question") -> 0 | G13: =IF($B13=0,0,C13/$B13) -> 0
A14: Total | B14: =SUM(B5:B13) -> 463 | C14: =SUM(C5:C13) -> 0 | D14: =SUM(D5:D13) -> 0 | E14: =SUM(E5:E13) -> 0 | F14: =SUM(F5:F13) -> 0 | G14: =IF($B14=0,0,C14/$B14) -> 0

Sheet Translations
A1: ReCOGnAIze · /parkwayshenton: English → Malay (Bahasa Melayu) review
A2: Fill in the yellow columns only (Status, Suggested text, Comments). Grey rows are previews of how split lines read when joined; orange cells stay in English.
A4: ID | B4: Screen | C4: Section | D4: What it is | E4: Shown when | F4: English (source) | G4: Malay (current) | H4: Notes for translator | I4: Status | J4: Suggested text | K4: Comments
A5: 1 | B5: 1 · Landing (/parkwayshenton) | C5: Browser tab & link preview | D5: Browser tab title | F5: Brain Health Check | ReCOGnAIze | G5: Pemeriksaan Kesihatan Otak | ReCOGnAIze
A6: 2 | B6: 1 · Landing (/parkwayshenton) | C6: Browser tab & link preview | D6: Search result description | F6: You track your heart, your sleep, your blood sugar. This is the same idea for your brain: a 3-minute check and a score you can act on. | G6: Anda pantau jantung, tidur dan gula dalam darah. Ini idea yang sama untuk otak anda: pemeriksaan 3 minit dan skor yang boleh anda gunakan. | H6: Not on screen: shown by Google and link previews.
A7: 3 | B7: 1 · Landing (/parkwayshenton) | C7: Browser tab & link preview | D7: Link preview title | F7: You tracked everything. What about your brain? | G7: Anda pantau segalanya. Bagaimana dengan otak anda? | H7: Not on screen: shown when the link is shared (WhatsApp etc.).
A8: 4 | B8: 1 · Landing (/parkwayshenton) | C8: Browser tab & link preview | D8: Link preview description | F8: Take a 3-min quiz and find out how your brain is performing. | G8: Ambil kuiz 3 minit dan ketahui prestasi otak anda. | H8: Not on screen: shown when the link is shared.
A9: 5 | B9: 1 · Landing (/parkwayshenton) | C9: Hero | D9: Credibility pill (top) | F9: Clinically validated at NTU LKCMedicine | G9: Disahkan secara klinikal di NTU LKCMedicine
A10: P1 | B10: 1 · Landing (/parkwayshenton) | C10: Hero | D10: Headline, as shown (two lines) | F10: You tracked everything / What about your brain? | G10: Anda pantau segalanya / Bagaimana dengan otak anda? | H10: Preview only. " / " marks the line break. Italic words: heroLine1Emph and heroLine2Emph. Put corrections on the rows below.
A11: 6 | B11: 1 · Landing (/parkwayshenton) | C11: Hero | D11: Headline line 1 — start | F11: You tracked | G11: Anda pantau | H11: Fragment. Followed directly by the italic word on the next row.
A12: 7 | B12: 1 · Landing (/parkwayshenton) | C12: Hero | D12: Headline line 1 — italic word | F12: everything | G12: segalanya | H12: Fragment, set in italics.
A13: 8 | B13: 1 · Landing (/parkwayshenton) | C13: Hero | D13: Headline line 2 — start | F13: What about your | G13: Bagaimana dengan | H13: Fragment. Followed directly by the italic word on the next row.
A14: 9 | B14: 1 · Landing (/parkwayshenton) | C14: Hero | D14: Headline line 2 — italic word | F14: brain | G14: otak | H14: Fragment, set in italics.
A15: 10 | B15: 1 · Landing (/parkwayshenton) | C15: Hero | D15: Headline line 2 — end | F15: ? | G15: anda? | H15: Fragment. Closes line 2.
A16: 11 | B16: 1 · Landing (/parkwayshenton) | C16: Hero | D16: Sub-headline | F16: Take a 3-min quiz and find out how your brain is performing | G16: Ambil kuiz 3 minit dan ketahui prestasi otak anda
A17: 12 | B17: 1 · Landing (/parkwayshenton) | C17: Language picker | D17: Picker label (screen readers) | F17: Choose your language | G17: Pilih bahasa anda | H17: Read aloud by screen readers; not printed on screen.
A18: 13 | B18: 1 · Landing (/parkwayshenton) | C18: Language picker | D18: Language names on the picker | F18: English | G18: Bahasa Melayu | H18: Each language's name is written in that language, and the picker shows all three whichever is selected. Only check that Bahasa Melayu is the name you'd expect.
A19: 14 | B19: 1 · Landing (/parkwayshenton) | C19: Sign-up form | D19: Name field placeholder | F19: Your name | G19: Nama anda
A20: 15 | B20: 1 · Landing (/parkwayshenton) | C20: Sign-up form | D20: Name field label (screen readers) | F20: Name | G20: Nama | H20: Read aloud by screen readers; not printed on screen.
A21: 16 | B21: 1 · Landing (/parkwayshenton) | C21: Sign-up form | D21: Email field placeholder | F21: your@email.com | G21: anda@emel.com | H21: An example address, not a sentence.
A22: 17 | B22: 1 · Landing (/parkwayshenton) | C22: Sign-up form | D22: Email field label (screen readers) | F22: Email | G22: E-mel | H22: Read aloud by screen readers; not printed on screen.
A23: 18 | B23: 1 · Landing (/parkwayshenton) | C23: Consent 1 · Gray Matter Solutions | D23: Line above the first tickbox | F23: I hereby confirm that I am submitting this form: | G23: Saya dengan ini mengesahkan bahawa saya menghantar borang ini:
A24: 19 | B24: 1 · Landing (/parkwayshenton) | C24: Consent 1 · Gray Matter Solutions | D24: Tickbox 1 — first sentence | F24: On my own behalf; or on behalf of another person, and I confirm that I am authorized to provide the answers in this form. | G24: Bagi pihak diri saya sendiri; atau bagi pihak orang lain, dan saya mengesahkan bahawa saya diberi kuasa untuk memberikan jawapan dalam borang ini.
A25: 20 | B25: 1 · Landing (/parkwayshenton) | C25: Consent 1 · Gray Matter Solutions | D25: Tickbox 1 — second sentence (in bold) | F25: By registering, I consent for Gray Matter Solutions to contact me with emails and newsletters. | G25: Dengan mendaftar, saya bersetuju untuk dihubungi oleh Gray Matter Solutions melalui e-mel dan surat berita. | H25: Required consent. Printed in bold.
A26: 21 | B26: 1 · Landing (/parkwayshenton) | C26: Consent 2 · IHH Healthcare Singapore (legal) | D26: Label above the second tickbox | F26: We need your consent on | G26: Kami perlukan kebenaran anda | H26: The rows after this one are IHH's consent. English is IHH's own legal wording; the Malay is our in-house translation of it, not IHH's, so it must say exactly what the English says, no more and no less.
A27: P2 | B27: 1 · Landing (/parkwayshenton) | C27: Consent 2 · IHH Healthcare Singapore (legal) | D27: Clause 1, as shown | F27: By providing the information set out in this form, I consent to IHH Healthcare Singapore and their representatives and/or agents collecting, using and disclosing my personal data to provide me with medical treatment and other reasonably related purposes. Such purposes are set out in the IHH Healthcare Singapore Data Protection Notice, or available on request. | G27: Dengan memberikan maklumat yang dinyatakan dalam borang ini, saya bersetuju untuk IHH Healthcare Singapore serta wakil dan/atau ejen mereka mengumpul, menggunakan dan mendedahkan data peribadi saya bagi memberikan rawatan perubatan kepada saya dan bagi tujuan lain yang berkaitan secara munasabah. Tujuan-tujuan tersebut dinyatakan dalam Notis Perlindungan Data IHH Healthcare Singapore, atau boleh didapati atas permintaan. | H27: LEGAL TEXT (IHH): must say exactly what the English says. See How to use. Preview only: the three rows below joined. The notice's name is a link.
A28: 22 | B28: 1 · Landing (/parkwayshenton) | C28: Consent 2 · IHH Healthcare Singapore (legal) | D28: Clause 1 — start | F28: By providing the information set out in this form, I consent to IHH Healthcare Singapore and their representatives and/or agents collecting, using and disclosing my personal data to provide me with medical treatment and other reasonably related purposes. Such purposes are set out in the | G28: Dengan memberikan maklumat yang dinyatakan dalam borang ini, saya bersetuju untuk IHH Healthcare Singapore serta wakil dan/atau ejen mereka mengumpul, menggunakan dan mendedahkan data peribadi saya bagi memberikan rawatan perubatan kepada saya dan bagi tujuan lain yang berkaitan secara munasabah. Tujuan-tujuan tersebut dinyatakan dalam | H28: LEGAL TEXT (IHH): must say exactly what the English says. See How to use. Fragment: followed directly by the notice's name.
A29: 23 | B29: 1 · Landing (/parkwayshenton) | C29: Consent 2 · IHH Healthcare Singapore (legal) | D29: Clause 1 — name of IHH's notice (link) | F29: IHH Healthcare Singapore Data Protection Notice | G29: Notis Perlindungan Data IHH Healthcare Singapore | H29: LEGAL TEXT (IHH): must say exactly what the English says. See How to use. Fragment: shown underlined, as a link.
A30: 24 | B30: 1 · Landing (/parkwayshenton) | C30: Consent 2 · IHH Healthcare Singapore (legal) | D30: Clause 1 — end | F30: , or available on request. | G30: , atau boleh didapati atas permintaan. | H30: LEGAL TEXT (IHH): must say exactly what the English says. See How to use. Fragment: closes clause 1.
A31: 25 | B31: 1 · Landing (/parkwayshenton) | C31: Consent 2 · IHH Healthcare Singapore (legal) | D31: Clause 2 — marketing | F31: I also consent to IHH Healthcare Singapore, their representatives, agents and/or business partners collecting, using and disclosing my personal data for marketing and promotional purposes. | G31: Saya juga bersetuju untuk IHH Healthcare Singapore, wakil, ejen dan/atau rakan niaga mereka mengumpul, menggunakan dan mendedahkan data peribadi saya bagi tujuan pemasaran dan promosi. | H31: LEGAL TEXT (IHH): must say exactly what the English says. See How to use.
A32: 26 | B32: 1 · Landing (/parkwayshenton) | C32: Consent 2 · IHH Healthcare Singapore (legal) | D32: Clause 3 — Do-Not-Call | F32: I agree to receiving marketing messages via SMS, telephone call and other Singapore phone number-based messaging, regardless of my registration with the Do-Not-Call registry. | G32: Saya bersetuju untuk menerima mesej pemasaran melalui SMS, panggilan telefon dan perkhidmatan pesanan lain yang berasaskan nombor telefon Singapura, tanpa mengira sama ada saya berdaftar dengan Daftar Jangan Hubungi (Do-Not-Call Registry). | H32: LEGAL TEXT (IHH): must say exactly what the English says. See How to use. "Do-Not-Call Registry" is kept in English in brackets on purpose, so it's clear which registry is meant.
A33: 27 | B33: 1 · Landing (/parkwayshenton) | C33: Error messages (form) | D33: No name entered | F33: Please enter your name. | G33: Sila masukkan nama anda.
A34: 28 | B34: 1 · Landing (/parkwayshenton) | C34: Error messages (form) | D34: Invalid email | F34: Please enter a valid email address. | G34: Sila masukkan alamat e-mel yang sah.
A35: 29 | B35: 1 · Landing (/parkwayshenton) | C35: Error messages (form) | D35: Tickbox 1 not ticked | F35: Please agree to the required consent to continue. | G35: Sila setujui kebenaran yang diperlukan untuk meneruskan.
A36: 30 | B36: 1 · Landing (/parkwayshenton) | C36: Error messages (form) | D36: Tickbox 2 not ticked | F36: Please also agree to IHH Healthcare Singapore's consent to continue. | G36: Sila juga bersetuju dengan kebenaran IHH Healthcare Singapore untuk meneruskan. | H36: "IHH Healthcare Singapore" stays in English as a proper name.
A37: 31 | B37: 1 · Landing (/parkwayshenton) | C37: Error messages (form) | D37: Save failed | F37: We couldn't save that. Please try again. | G37: Kami tidak dapat menyimpannya. Sila cuba lagi.
A38: 32 | B38: 1 · Landing (/parkwayshenton) | C38: Start button | D38: Button | F38: Get started for free | G38: Mula secara percuma
A39: 33 | B39: 1 · Landing (/parkwayshenton) | C39: Start button | D39: Button while saving | F39: Saving… | G39: Menyimpan…
A40: 34 | B40: 1 · Landing (/parkwayshenton) | C40: Press rail | D40: Label over the press logos | F40: As featured in | G40: Disiarkan di
A41: P3 | B41: 1 · Landing (/parkwayshenton) | C41: Fine print (below the video) | D41: Paragraph 1, as shown | F41: By registering, you agree for Gray Matter Solutions Pte Ltd and its related corporations and/or third-party service providers to collect, store, process and/or disclose your personal data for the purpose of sending you your assessment results, electronic direct mailers (EDMs), newsletters, and invitations to talks and events organised by us. You can unsubscribe at any time by clicking the link in the footer of our emails. For more information about our privacy practices, refer to our Privacy Policy. | G41: Dengan mendaftar, anda bersetuju untuk Gray Matter Solutions Pte Ltd dan syarikat berkaitannya dan/atau penyedia perkhidmatan pihak ketiga mengumpul, menyimpan, memproses dan/atau mendedahkan data peribadi anda bagi tujuan menghantar keputusan penilaian anda, mel terus elektronik (EDM), surat berita, serta jemputan ke ceramah dan acara yang dianjurkan oleh kami. Anda boleh berhenti melanggan pada bila-bila masa dengan mengklik pautan di bahagian bawah e-mel kami. Untuk maklumat lanjut tentang amalan privasi kami, rujuk Dasar Privasi kami. | H41: Preview only: the three rows below joined. The policy name is a link.
...
