Workbook

Sheet How to use
A1: ReCOGnAIze · /parkwayshenton translation review
A2: Every visitor-facing string in the Parkway Shenton flow, in English, Chinese (中文) and Malay (Bahasa Melayu), in the order a visitor meets them. Generated from the app's copy files at commit 9efce8d.
A4: What to do
A5: 1. Read | B5: On the Translations tab, read each row's English, then the current Chinese and Malay. The English is the source; the Chinese and Malay are what the app shows today.
A6: 2. Mark a status | B6: In "Chinese: status" and "Malay: status", pick OK, Change needed or Question from the dropdown.
A7: 3. Suggest a fix | B7: For Change needed, type the full corrected text in the "suggested text" column (the whole string, not just the changed word).
A8: 4. Comment | B8: Use "Translator comments" for anything else: a question, a note on tone, a term to use consistently.
A9: Only edit | B9: The yellow columns J to N. Everything else is copied from the app's code, so please don't edit it; put changes in the suggested-text columns.
A11: Example of a filled-in row (illustration only, not a real review)
A12: English | B12: Get started for free
A13: Chinese (current) | B13: 免费开始
A14: Chinese: status | B14: Change needed
A15: Chinese: suggested | B15: 免费开始检测
A16: Comment | B16: "开始" alone reads as "start" with no object; adding 检测 says what is being started.
A18: Reading the rows
A19: {placeholders} | B19: Text in curly brackets, such as {name}, {percentile} or {ageLabel}, is replaced by a live value. Keep it exactly as written, but move it wherever it reads naturally.
A20: Grey rows | B20: "Assembled preview" rows show a sentence that the screen builds from several rows (for example a headline with one word in italics, or a clause with a link in the middle). Use the preview to judge how the sentence reads; put corrections on the individual rows beneath it.
A21: Fragments | B21: Rows marked "Fragment" are pieces of one sentence. Spaces at the start or end are part of the text and matter.
A22: Orange cells | B22: Text that is hardcoded in English and stays English in every language (for example a journal title, or game-screen text with no translation yet). Mark it Change needed if it should be translated.
A23: Red rows (legal) | B23: IHH Healthcare Singapore's consent clauses. The English is IHH's own legal wording; the Chinese and Malay are our in-house translations, not IHH's. They must say exactly what the English says, no more and no less.
A24: Shown when | B24: Blank means the text is always shown. The report comes in four versions (under 40 / 40 and over × fast / slower result); report rows name the versions they appear in.
A25: Screen readers | B25: Rows marked "screen readers" are not printed on screen but are read aloud to visually impaired visitors. Please still translate them.
A27: Tabs
A28: Translations | B28: The flow, screen by screen: landing, what happens next, game intro, tutorial and game, game complete, quiz, loading, report.
A29: Progress | B29: Counts per screen, filled in automatically from the statuses.
A30: Not linked (optional) | B30: The "full picture" page (/parkwayshenton/report-full). It is translated but nothing in the flow links to it at the moment. Review only if time allows.
A32: Not in this sheet
A33: Result email | B33: The email with the visitor's result is sent in English whatever language they picked, by design, so it isn't here.
A34: Brand & proper names | B34: ReCOGnAIze, Gray Matter Solutions, IHH Healthcare Singapore, BrainScan and the press logos are shown as they are and are not listed separately.

Sheet Progress
A1: Review progress by screen
A2: Counts update as statuses are filled in on the Translations tab. Preview (grey) rows are not counted.
A4: Screen | B4: Strings | C4: Chinese reviewed | D4: Chinese: change needed | E4: Chinese: question | F4: Malay reviewed | G4: Malay: change needed | H4: Malay: question | I4: % reviewed (both)
A5: 1 · Landing (/parkwayshenton) | B5: =COUNTIFS(Translations!$B$5:$B$450,$A5,Translations!$A$5:$A$450,">0") -> 44 | C5: =COUNTIFS(Translations!$B$5:$B$450,$A5,Translations!$A$5:$A$450,">0",Translations!$J$5:$J$450,"<>") -> 0 | D5: =COUNTIFS(Translations!$B$5:$B$450,$A5,Translations!$J$5:$J$450,"Change needed") -> 0 | E5: =COUNTIFS(Translations!$B$5:$B$450,$A5,Translations!$J$5:$J$450,"Question") -> 0 | F5: =COUNTIFS(Translations!$B$5:$B$450,$A5,Translations!$A$5:$A$450,">0",Translations!$L$5:$L$450,"<>") -> 0 | G5: =COUNTIFS(Translations!$B$5:$B$450,$A5,Translations!$L$5:$L$450,"Change needed") -> 0 | H5: =COUNTIFS(Translations!$B$5:$B$450,$A5,Translations!$L$5:$L$450,"Question") -> 0 | I5: =IF(B5=0,0,(C5+F5)/(2*B5)) -> 0
A6: 2 · What happens next (/parkwayshenton/ready) | B6: =COUNTIFS(Translations!$B$5:$B$450,$A6,Translations!$A$5:$A$450,">0") -> 13 | C6: =COUNTIFS(Translations!$B$5:$B$450,$A6,Translations!$A$5:$A$450,">0",Translations!$J$5:$J$450,"<>") -> 0 | D6: =COUNTIFS(Translations!$B$5:$B$450,$A6,Translations!$J$5:$J$450,"Change needed") -> 0 | E6: =COUNTIFS(Translations!$B$5:$B$450,$A6,Translations!$J$5:$J$450,"Question") -> 0 | F6: =COUNTIFS(Translations!$B$5:$B$450,$A6,Translations!$A$5:$A$450,">0",Translations!$L$5:$L$450,"<>") -> 0 | G6: =COUNTIFS(Translations!$B$5:$B$450,$A6,Translations!$L$5:$L$450,"Change needed") -> 0 | H6: =COUNTIFS(Translations!$B$5:$B$450,$A6,Translations!$L$5:$L$450,"Question") -> 0 | I6: =IF(B6=0,0,(C6+F6)/(2*B6)) -> 0
A7: 3 · Game intro (/parkwayshenton/challenge) | B7: =COUNTIFS(Translations!$B$5:$B$450,$A7,Translations!$A$5:$A$450,">0") -> 8 | C7: =COUNTIFS(Translations!$B$5:$B$450,$A7,Translations!$A$5:$A$450,">0",Translations!$J$5:$J$450,"<>") -> 0 | D7: =COUNTIFS(Translations!$B$5:$B$450,$A7,Translations!$J$5:$J$450,"Change needed") -> 0 | E7: =COUNTIFS(Translations!$B$5:$B$450,$A7,Translations!$J$5:$J$450,"Question") -> 0 | F7: =COUNTIFS(Translations!$B$5:$B$450,$A7,Translations!$A$5:$A$450,">0",Translations!$L$5:$L$450,"<>") -> 0 | G7: =COUNTIFS(Translations!$B$5:$B$450,$A7,Translations!$L$5:$L$450,"Change needed") -> 0 | H7: =COUNTIFS(Translations!$B$5:$B$450,$A7,Translations!$L$5:$L$450,"Question") -> 0 | I7: =IF(B7=0,0,(C7+F7)/(2*B7)) -> 0
A8: 4 · Tutorial & game (/symbol-matching) | B8: =COUNTIFS(Translations!$B$5:$B$450,$A8,Translations!$A$5:$A$450,">0") -> 28 | C8: =COUNTIFS(Translations!$B$5:$B$450,$A8,Translations!$A$5:$A$450,">0",Translations!$J$5:$J$450,"<>") -> 0 | D8: =COUNTIFS(Translations!$B$5:$B$450,$A8,Translations!$J$5:$J$450,"Change needed") -> 0 | E8: =COUNTIFS(Translations!$B$5:$B$450,$A8,Translations!$J$5:$J$450,"Question") -> 0 | F8: =COUNTIFS(Translations!$B$5:$B$450,$A8,Translations!$A$5:$A$450,">0",Translations!$L$5:$L$450,"<>") -> 0 | G8: =COUNTIFS(Translations!$B$5:$B$450,$A8,Translations!$L$5:$L$450,"Change needed") -> 0 | H8: =COUNTIFS(Translations!$B$5:$B$450,$A8,Translations!$L$5:$L$450,"Question") -> 0 | I8: =IF(B8=0,0,(C8+F8)/(2*B8)) -> 0
A9: 5 · Game complete (/parkwayshenton/game-complete) | B9: =COUNTIFS(Translations!$B$5:$B$450,$A9,Translations!$A$5:$A$450,">0") -> 7 | C9: =COUNTIFS(Translations!$B$5:$B$450,$A9,Translations!$A$5:$A$450,">0",Translations!$J$5:$J$450,"<>") -> 0 | D9: =COUNTIFS(Translations!$B$5:$B$450,$A9,Translations!$J$5:$J$450,"Change needed") -> 0 | E9: =COUNTIFS(Translations!$B$5:$B$450,$A9,Translations!$J$5:$J$450,"Question") -> 0 | F9: =COUNTIFS(Translations!$B$5:$B$450,$A9,Translations!$A$5:$A$450,">0",Translations!$L$5:$L$450,"<>") -> 0 | G9: =COUNTIFS(Translations!$B$5:$B$450,$A9,Translations!$L$5:$L$450,"Change needed") -> 0 | H9: =COUNTIFS(Translations!$B$5:$B$450,$A9,Translations!$L$5:$L$450,"Question") -> 0 | I9: =IF(B9=0,0,(C9+F9)/(2*B9)) -> 0
A10: 6 · Brain health quiz (/parkwayshenton/quiz) | B10: =COUNTIFS(Translations!$B$5:$B$450,$A10,Translations!$A$5:$A$450,">0") -> 114 | C10: =COUNTIFS(Translations!$B$5:$B$450,$A10,Translations!$A$5:$A$450,">0",Translations!$J$5:$J$450,"<>") -> 0 | D10: =COUNTIFS(Translations!$B$5:$B$450,$A10,Translations!$J$5:$J$450,"Change needed") -> 0 | E10: =COUNTIFS(Translations!$B$5:$B$450,$A10,Translations!$J$5:$J$450,"Question") -> 0 | F10: =COUNTIFS(Translations!$B$5:$B$450,$A10,Translations!$A$5:$A$450,">0",Translations!$L$5:$L$450,"<>") -> 0 | G10: =COUNTIFS(Translations!$B$5:$B$450,$A10,Translations!$L$5:$L$450,"Change needed") -> 0 | H10: =COUNTIFS(Translations!$B$5:$B$450,$A10,Translations!$L$5:$L$450,"Question") -> 0 | I10: =IF(B10=0,0,(C10+F10)/(2*B10)) -> 0
A11: 7 · Building your profile (/parkwayshenton/loading) | B11: =COUNTIFS(Translations!$B$5:$B$450,$A11,Translations!$A$5:$A$450,">0") -> 9 | C11: =COUNTIFS(Translations!$B$5:$B$450,$A11,Translations!$A$5:$A$450,">0",Translations!$J$5:$J$450,"<>") -> 0 | D11: =COUNTIFS(Translations!$B$5:$B$450,$A11,Translations!$J$5:$J$450,"Change needed") -> 0 | E11: =COUNTIFS(Translations!$B$5:$B$450,$A11,Translations!$J$5:$J$450,"Question") -> 0 | F11: =COUNTIFS(Translations!$B$5:$B$450,$A11,Translations!$A$5:$A$450,">0",Translations!$L$5:$L$450,"<>") -> 0 | G11: =COUNTIFS(Translations!$B$5:$B$450,$A11,Translations!$L$5:$L$450,"Change needed") -> 0 | H11: =COUNTIFS(Translations!$B$5:$B$450,$A11,Translations!$L$5:$L$450,"Question") -> 0 | I11: =IF(B11=0,0,(C11+F11)/(2*B11)) -> 0
A12: 8 · Report (/parkwayshenton/report) | B12: =COUNTIFS(Translations!$B$5:$B$450,$A12,Translations!$A$5:$A$450,">0") -> 203 | C12: =COUNTIFS(Translations!$B$5:$B$450,$A12,Translations!$A$5:$A$450,">0",Translations!$J$5:$J$450,"<>") -> 0 | D12: =COUNTIFS(Translations!$B$5:$B$450,$A12,Translations!$J$5:$J$450,"Change needed") -> 0 | E12: =COUNTIFS(Translations!$B$5:$B$450,$A12,Translations!$J$5:$J$450,"Question") -> 0 | F12: =COUNTIFS(Translations!$B$5:$B$450,$A12,Translations!$A$5:$A$450,">0",Translations!$L$5:$L$450,"<>") -> 0 | G12: =COUNTIFS(Translations!$B$5:$B$450,$A12,Translations!$L$5:$L$450,"Change needed") -> 0 | H12: =COUNTIFS(Translations!$B$5:$B$450,$A12,Translations!$L$5:$L$450,"Question") -> 0 | I12: =IF(B12=0,0,(C12+F12)/(2*B12)) -> 0
A13: Total | B13: =SUM(B5:B12) -> 426 | C13: =SUM(C5:C12) -> 0 | D13: =SUM(D5:D12) -> 0 | E13: =SUM(E5:E12) -> 0 | F13: =SUM(F5:F12) -> 0 | G13: =SUM(G5:G12) -> 0 | H13: =SUM(H5:H12) -> 0 | I13: =IF(B13=0,0,(C13+F13)/(2*B13)) -> 0

Sheet Translations
A1: ReCOGnAIze · /parkwayshenton: English → Chinese & Malay review
A2: Fill in the yellow columns only (J to N). Status: pick OK, Change needed or Question. Grey rows are previews of how split lines read when joined; orange cells stay in English in every language.
A4: # | B4: Screen | C4: Section | D4: What it is | E4: Shown when | F4: English (source) | G4: Chinese 中文 (current) | H4: Malay (current) | I4: Notes for translator | J4: Chinese: status | K4: Chinese: suggested text | L4: Malay: status | M4: Malay: suggested text | N4: Translator comments | O4: Source in code (file › key)
A5: 1 | B5: 1 · Landing (/parkwayshenton) | C5: Browser tab & link preview | D5: Browser tab title | F5: Brain Health Check | ReCOGnAIze | G5: 脑健康检查 | ReCOGnAIze | H5: Pemeriksaan Kesihatan Otak | ReCOGnAIze | O5: liteEventCopy › landing.headTitle
A6: 2 | B6: 1 · Landing (/parkwayshenton) | C6: Browser tab & link preview | D6: Search result description | F6: You track your heart, your sleep, your blood sugar. This is the same idea for your brain: a 3-minute check and a score you can act on. | G6: 您会关注心脏、睡眠和血糖。大脑同样值得关注：3 分钟检测，一个可以据以行动的分数。 | H6: Anda pantau jantung, tidur dan gula dalam darah. Ini idea yang sama untuk otak anda: pemeriksaan 3 minit dan skor yang boleh anda gunakan. | I6: Not on screen: shown by Google and link previews. | O6: liteEventCopy › landing.metaDescription
A7: 3 | B7: 1 · Landing (/parkwayshenton) | C7: Browser tab & link preview | D7: Link preview title | F7: You tracked everything. What about your brain? | G7: 什么都追踪了，那大脑呢？ | H7: Anda pantau segalanya. Bagaimana dengan otak anda? | I7: Not on screen: shown when the link is shared (WhatsApp etc.). | O7: liteEventCopy › landing.ogTitle
A8: 4 | B8: 1 · Landing (/parkwayshenton) | C8: Browser tab & link preview | D8: Link preview description | F8: Take a 3-min quiz and find out how your brain is performing. | G8: 花 3 分钟做个测试，看看您的大脑表现如何。 | H8: Ambil kuiz 3 minit dan ketahui prestasi otak anda. | I8: Not on screen: shown when the link is shared. | O8: liteEventCopy › landing.ogDescription
A9: 5 | B9: 1 · Landing (/parkwayshenton) | C9: Hero | D9: Credibility pill (top) | F9: Clinically validated at NTU LKCMedicine | G9: 经南洋理工大学李光前医学院临床验证 | H9: Disahkan secara klinikal di NTU LKCMedicine | O9: liteEventCopy › landing.pill
B10: 1 · Landing (/parkwayshenton) | C10: Hero | D10: Headline, as shown (two lines) | F10: You tracked everything / What about your brain? | G10: 您什么都追踪了 / 那您的大脑呢？ | H10: Anda pantau segalanya / Bagaimana dengan otak anda? | I10: Preview only. " / " marks the line break. Italic words: heroLine1Emph and heroLine2Emph. Put corrections on the rows below. | O10: (assembled preview)
A11: 6 | B11: 1 · Landing (/parkwayshenton) | C11: Hero | D11: Headline line 1 — start | F11: You tracked | G11: 您什么都 | H11: Anda pantau | I11: Fragment. Followed directly by the italic word on the next row. | O11: liteEventCopy › landing.heroLine1Lead
A12: 7 | B12: 1 · Landing (/parkwayshenton) | C12: Hero | D12: Headline line 1 — italic word | F12: everything | G12: 追踪了 | H12: segalanya | I12: Fragment, set in italics. | O12: liteEventCopy › landing.heroLine1Emph
A13: 8 | B13: 1 · Landing (/parkwayshenton) | C13: Hero | D13: Headline line 2 — start | F13: What about your | G13: 那您的 | H13: Bagaimana dengan | I13: Fragment. Followed directly by the italic word on the next row. | O13: liteEventCopy › landing.heroLine2Lead
A14: 9 | B14: 1 · Landing (/parkwayshenton) | C14: Hero | D14: Headline line 2 — italic word | F14: brain | G14: 大脑 | H14: otak | I14: Fragment, set in italics. | O14: liteEventCopy › landing.heroLine2Emph
A15: 10 | B15: 1 · Landing (/parkwayshenton) | C15: Hero | D15: Headline line 2 — end | F15: ? | G15: 呢？ | H15: anda? | I15: Fragment. Closes line 2. | O15: liteEventCopy › landing.heroLine2Tail
A16: 11 | B16: 1 · Landing (/parkwayshenton) | C16: Hero | D16: Sub-headline | F16: Take a 3-min quiz and find out how your brain is performing | G16: 花 3 分钟做个测试，看看您的大脑表现如何 | H16: Ambil kuiz 3 minit dan ketahui prestasi otak anda | O16: liteEventCopy › landing.heroSub
A17: 12 | B17: 1 · Landing (/parkwayshenton) | C17: Language picker | D17: Picker label (screen readers) | F17: Choose your language | G17: 选择语言 | H17: Pilih bahasa anda | I17: Read aloud by screen readers; not printed on screen. | O17: liteEventCopy › picker.label
A18: 13 | B18: 1 · Landing (/parkwayshenton) | C18: Language picker | D18: Language names on the picker | F18: English | G18: 中文 | H18: Bahasa Melayu | I18: Each language's name is written in that language, and the picker shows all three whichever is selected. Only check that 中文 and Bahasa Melayu are the names you'd expect. | O18: liteEvent › LANG_LABELS
A19: 14 | B19: 1 · Landing (/parkwayshenton) | C19: Sign-up form | D19: Name field placeholder | F19: Your name | G19: 您的姓名 | H19: Nama anda | O19: liteEventCopy › results.namePlaceholder
A20: 15 | B20: 1 · Landing (/parkwayshenton) | C20: Sign-up form | D20: Name field label (screen readers) | F20: Name | G20: 姓名 | H20: Nama | I20: Read aloud by screen readers; not printed on screen. | O20: liteEventCopy › results.nameLabel
A21: 16 | B21: 1 · Landing (/parkwayshenton) | C21: Sign-up form | D21: Email field placeholder | F21: your@email.com | G21: your@email.com | H21: anda@emel.com | I21: An example address, not a sentence. | O21: liteEventCopy › results.emailPlaceholder
A22: 17 | B22: 1 · Landing (/parkwayshenton) | C22: Sign-up form | D22: Email field label (screen readers) | F22: Email | G22: 电邮 | H22: E-mel | I22: Read aloud by screen readers; not printed on screen. | O22: liteEventCopy › results.emailLabel
A23: 18 | B23: 1 · Landing (/parkwayshenton) | C23: Consent 1 · Gray Matter Solutions | D23: Line above the first tickbox | F23: I hereby confirm that I am submitting this form: | G23: 我在此确认，我提交此表格： | H23: Saya dengan ini mengesahkan bahawa saya menghantar borang ini: | O23: clinicSignupConsentCopy › heading
A24: 19 | B24: 1 · Landing (/parkwayshenton) | C24: Consent 1 · Gray Matter Solutions | D24: Tickbox 1 — first sentence | F24: On my own behalf; or on behalf of another person, and I confirm that I am authorized to provide the answers in this form. | G24: 以本人名义提交；或代表他人提交，并确认本人已获授权在此表格中提供相关答案。 | H24: Bagi pihak diri saya sendiri; atau bagi pihak orang lain, dan saya mengesahkan bahawa saya diberi kuasa untuk memberikan jawapan dalam borang ini. | O24: clinicSignupConsentCopy › ownBehalf
A25: 20 | B25: 1 · Landing (/parkwayshenton) | C25: Consent 1 · Gray Matter Solutions | D25: Tickbox 1 — second sentence (in bold) | F25: By registering, I consent for Gray Matter Solutions to contact me with emails and newsletters. | G25: 注册即表示本人同意 Gray Matter Solutions 通过电子邮件与通讯与本人联系。 | H25: Dengan mendaftar, saya bersetuju untuk dihubungi oleh Gray Matter Solutions melalui e-mel dan surat berita. | I25: Required consent. Printed in bold. | O25: clinicSignupConsentCopy › consent
A26: 21 | B26: 1 · Landing (/parkwayshenton) | C26: Consent 2 · IHH Healthcare Singapore (legal) | D26: Label above the second tickbox | F26: We need your consent on | G26: 我们需要您的同意 | H26: Kami perlukan kebenaran anda | I26: The rows after this one are IHH's consent. English is IHH's own legal wording; the Chinese and Malay are our in-house translations of it, not IHH's, so they must say exactly what the English says, no more and no less. | O26: parkwayConsentCopy › eyebrow
B27: 1 · Landing (/parkwayshenton) | C27: Consent 2 · IHH Healthcare Singapore (legal) | D27: Clause 1, as shown | F27: By providing the information set out in this form, I consent to IHH Healthcare Singapore and their representatives and/or agents collecting, using and disclosing my personal data to provide me with medical treatment and other reasonably related purposes. Such purposes are set out in the IHH Healthcare Singapore Data Protection Notice, or available on request. | G27: 提供本表格所列的信息，即表示本人同意 IHH Healthcare Singapore 及其代表和／或代理人收集、使用及披露本人的个人资料，用于为本人提供医疗治疗以及其他合理相关的用途。相关用途详载于《IHH Healthcare Singapore 资料保护通知》，亦可应要求索取。 | H27: Dengan memberikan maklumat yang dinyatakan dalam borang ini, saya bersetuju untuk IHH Healthcare Singapore serta wakil dan/atau ejen mereka mengumpul, menggunakan dan mendedahkan data peribadi saya bagi memberikan rawatan perubatan kepada saya dan bagi tujuan lain yang berkaitan secara munasabah. Tujuan-tujuan tersebut dinyatakan dalam Notis Perlindungan Data IHH Healthcare Singapore, atau boleh didapati atas permintaan. | I27: LEGAL TEXT (IHH): must say exactly what the English says. See How to use. Preview only: the three rows below joined. The notice's name is a link. | O27: (assembled preview)
A28: 22 | B28: 1 · Landing (/parkwayshenton) | C28: Consent 2 · IHH Healthcare Singapore (legal) | D28: Clause 1 — start | F28: By providing the information set out in this form, I consent to IHH Healthcare Singapore and their representatives and/or agents collecting, using and disclosing my personal data to provide me with medical treatment and other reasonably related purposes. Such purposes are set out in the | G28: 提供本表格所列的信息，即表示本人同意 IHH Healthcare Singapore 及其代表和／或代理人收集、使用及披露本人的个人资料，用于为本人提供医疗治疗以及其他合理相关的用途。相关用途详载于《 | H28: Dengan memberikan maklumat yang dinyatakan dalam borang ini, saya bersetuju untuk IHH Healthcare Singapore serta wakil dan/atau ejen mereka mengumpul, menggunakan dan mendedahkan data peribadi saya bagi memberikan rawatan perubatan kepada saya dan bagi tujuan lain yang berkaitan secara munasabah. Tujuan-tujuan tersebut dinyatakan dalam | I28: LEGAL TEXT (IHH): must say exactly what the English says. See How to use. Fragment: followed directly by the notice's name. | O28: parkwayShentonConsentCopy (EN from parkwayConsentCopy) › clauses.treatmentLead
A29: 23 | B29: 1 · Landing (/parkwayshenton) | C29: Consent 2 · IHH Healthcare Singapore (legal) | D29: Clause 1 — name of IHH's notice (link) | F29: IHH Healthcare Singapore Data Protection Notice | G29: IHH Healthcare Singapore 资料保护通知 | H29: Notis Perlindungan Data IHH Healthcare Singapore | I29: LEGAL TEXT (IHH): must say exactly what the English says. See How to use. Fragment: shown underlined, as a link. | O29: parkwayShentonConsentCopy (EN from parkwayConsentCopy) › clauses.noticeName
A30: 24 | B30: 1 · Landing (/parkwayshenton) | C30: Consent 2 · IHH Healthcare Singapore (legal) | D30: Clause 1 — end | F30: , or available on request. | G30: 》，亦可应要求索取。 | H30: , atau boleh didapati atas permintaan. | I30: LEGAL TEXT (IHH): must say exactly what the English says. See How to use. Fragment: closes clause 1. | O30: parkwayShentonConsentCopy (EN from parkwayConsentCopy) › clauses.treatmentTail
A31: 25 | B31: 1 · Landing (/parkwayshenton) | C31: Consent 2 · IHH Healthcare Singapore (legal) | D31: Clause 2 — marketing | F31: I also consent to IHH Healthcare Singapore, their representatives, agents and/or business partners collecting, using and disclosing my personal data for marketing and promotional purposes. | G31: 本人亦同意 IHH Healthcare Singapore 及其代表、代理人和／或业务伙伴收集、使用及披露本人的个人资料，用于营销及推广用途。 | H31: Saya juga bersetuju untuk IHH Healthcare Singapore, wakil, ejen dan/atau rakan niaga mereka mengumpul, menggunakan dan mendedahkan data peribadi saya bagi tujuan pemasaran dan promosi. | I31: LEGAL TEXT (IHH): must say exactly what the English says. See How to use. | O31: parkwayShentonConsentCopy (EN from parkwayConsentCopy) › clauses.marketing
A32: 26 | B32: 1 · Landing (/parkwayshenton) | C32: Consent 2 · IHH Healthcare Singapore (legal) | D32: Clause 3 — Do-Not-Call | F32: I agree to receiving marketing messages via SMS, telephone call and other Singapore phone number-based messaging, regardless of my registration with the Do-Not-Call registry. | G32: 本人同意通过短信（SMS）、电话及其他以新加坡电话号码为基础的通讯方式接收营销信息，无论本人是否已在谢绝来电登记处（Do-Not-Call Registry）登记。 | H32: Saya bersetuju untuk menerima mesej pemasaran melalui SMS, panggilan telefon dan perkhidmatan pesanan lain yang berasaskan nombor telefon Singapura, tanpa mengira sama ada saya berdaftar dengan Daftar Jangan Hubungi (Do-Not-Call Registry). | I32: LEGAL TEXT (IHH): must say exactly what the English says. See How to use. "Do-Not-Call Registry" is kept in English in brackets on purpose, so it's clear which registry is meant. | O32: parkwayShentonConsentCopy (EN from parkwayConsentCopy) › clauses.dnc
A33: 27 | B33: 1 · Landing (/parkwayshenton) | C33: Error messages (form) | D33: No name entered | F33: Please enter your name. | G33: 请输入您的姓名。 | H33: Sila masukkan nama anda. | O33: liteEventCopy › results.errName
A34: 28 | B34: 1 · Landing (/parkwayshenton) | C34: Error messages (form) | D34: Invalid email | F34: Please enter a valid email address. | G34: 请输入有效的电邮地址。 | H34: Sila masukkan alamat e-mel yang sah. | O34: liteEventCopy › results.errEmail
A35: 29 | B35: 1 · Landing (/parkwayshenton) | C35: Error messages (form) | D35: Tickbox 1 not ticked | F35: Please agree to the required consent to continue. | G35: 请勾选必填的同意项以继续。 | H35: Sila setujui kebenaran yang diperlukan untuk meneruskan. | O35: liteEventCopy › results.errConsent
A36: 30 | B36: 1 · Landing (/parkwayshenton) | C36: Error messages (form) | D36: Tickbox 2 not ticked | F36: Please also agree to IHH Healthcare Singapore's consent to continue. | G36: 请同时同意 IHH Healthcare Singapore 的条款以继续。 | H36: Sila juga bersetuju dengan kebenaran IHH Healthcare Singapore untuk meneruskan. | I36: "IHH Healthcare Singapore" stays in English as a proper name. | O36: parkwayShentonConsentCopy › errConsent
A37: 31 | B37: 1 · Landing (/parkwayshenton) | C37: Error messages (form) | D37: Save failed | F37: We couldn't save that. Please try again. | G37: 保存失败，请再试一次。 | H37: Kami tidak dapat menyimpannya. Sila cuba lagi. | O37: liteEventCopy › results.errSave
A38: 32 | B38: 1 · Landing (/parkwayshenton) | C38: Start button | D38: Button | F38: Get started for free | G38: 免费开始 | H38: Mula secara percuma | O38: liteEventCopy › landing.cta
A39: 33 | B39: 1 · Landing (/parkwayshenton) | C39: Start button | D39: Button while saving | F39: Saving… | G39: 正在保存… | H39: Menyimpan… | O39: liteEventCopy › results.saving
A40: 34 | B40: 1 · Landing (/parkwayshenton) | C40: Press rail | D40: Label over the press logos | F40: As featured in | G40: 媒体报道 | H40: Disiarkan di | O40: liteEventCopy › landing.featuredIn
B41: 1 · Landing (/parkwayshenton) | C41: Fine print (below the video) | D41: Paragraph 1, as shown | F41: By registering, you agree for Gray Matter Solutions Pte Ltd and its related corporations and/or third-party service providers to collect, store, process and/or disclose your personal data for the purpose of sending you your assessment results, electronic direct mailers (EDMs), newsletters, and invitations to talks and events organised by us. You can unsubscribe at any time by clicking the link in the footer of our emails. For more information about our privacy practices, refer to our Privacy Policy. | G41: 注册即表示您同意 Gray Matter Solutions Pte Ltd 及其关联公司和／或第三方服务供应商收集、储存、处理和／或披露您的个人资料，用于向您发送评估结果、电子邮件通讯（EDM）、新闻通讯，以及由我方举办的讲座与活动邀请。您可随时点击邮件页脚的链接取消订阅。有关我们隐私做法的更多信息，请参阅我们的隐私政策。 | H41: Dengan mendaftar, anda bersetuju untuk Gray Matter Solutions Pte Ltd dan syarikat berkaitannya dan/atau penyedia perkhidmatan pihak ketiga mengumpul, menyimpan, memproses dan/atau mendedahkan data peribadi anda bagi tujuan menghantar keputusan penilaian anda, mel terus elektronik (EDM), surat berita, serta jemputan ke ceramah dan acara yang dianjurkan oleh kami. Anda boleh berhenti melanggan pada bila-bila masa dengan mengklik pautan di bahagian bawah e-mel kami. Untuk maklumat lanjut tentang amalan privasi kami, rujuk Dasar Privasi kami. | I41: Preview only: the three rows below joined. The policy name is a link. | O41: (assembled preview)
...

Sheet Not linked (optional)
A1: /parkwayshenton/report-full: translated but not linked from the flow (optional review)
A2: Fill in the yellow columns only (J to N). Status: pick OK, Change needed or Question. Grey rows are previews of how split lines read when joined; orange cells stay in English in every language.
A4: # | B4: Screen | C4: Section | D4: What it is | E4: Shown when | F4: English (source) | G4: Chinese 中文 (current) | H4: Malay (current) | I4: Notes for translator | J4: Chinese: status | K4: Chinese: suggested text | L4: Malay: status | M4: Malay: suggested text | N4: Translator comments | O4: Source in code (file › key)
A5: 1 | B5: Not linked · /parkwayshenton/report-full | D5: Browser tab title | F5: The full picture | ReCOGnAIze | G5: 完整版图 | ReCOGnAIze | H5: Gambaran penuh | ReCOGnAIze | O5: liteEventCopy › reportFull.headTitle
A6: 2 | B6: Not linked · /parkwayshenton/report-full | D6: Back link | F6: ← Back to your result | G6: ← 返回您的结果 | H6: ← Kembali ke keputusan anda | O6: liteEventCopy › reportFull.back
A7: 3 | B7: Not linked · /parkwayshenton/report-full | D7: Eyebrow | F7: The full picture | G7: 完整版图 | H7: Gambaran penuh | O7: liteEventCopy › reportFull.eyebrow
A8: 4 | B8: Not linked · /parkwayshenton/report-full | D8: Heading | F8: Take the complete brain health assessment | G8: 进行完整的脑健康评估 | H8: Ambil penilaian kesihatan otak yang lengkap | O8: liteEventCopy › reportFull.heading
A9: 5 | B9: Not linked · /parkwayshenton/report-full | D9: Research link | F9: Validated in peer-reviewed research | G9: 已在同行评审研究中获得验证 | H9: Disahkan dalam penyelidikan yang dinilai rakan sebaya | O9: liteEventCopy › reportFull.paperNote
A10: 6 | B10: Not linked · /parkwayshenton/report-full | D10: Product name | F10: BrainScan brain health assessment | G10: BrainScan 脑健康评估 | H10: Penilaian kesihatan otak BrainScan | O10: liteEventCopy › reportFull.offerName
A11: 7 | B11: Not linked · /parkwayshenton/report-full | D11: Product note | F11: Developed at NTU's Dementia Research Centre · Registered with Singapore's HSA | G11: 由南洋理工大学痴呆症研究中心开发 · 已在新加坡卫生科学局注册 | H11: Dibangunkan di Dementia Research Centre NTU · Berdaftar dengan HSA Singapura | O11: liteEventCopy › reportFull.offerNote
A12: 8 | B12: Not linked · /parkwayshenton/report-full | D12: What's included 1 of 3 | F12: Clinically-validated neuroscientific games to detect specific brain functions | G12: 经临床验证的神经科学游戏，用于检测特定的大脑功能 | H12: Permainan neurosains yang disahkan secara klinikal untuk mengesan fungsi otak tertentu | O12: liteEventCopy › reportFull.includes.0
A13: 9 | B13: Not linked · /parkwayshenton/report-full | D13: What's included 2 of 3 | F13: All four cognitive domains: processing speed, memory, attention and executive function | G13: 涵盖四大认知领域：处理速度、记忆、注意力与执行功能 | H13: Kesemua empat domain kognitif: kelajuan pemprosesan, memori, perhatian dan fungsi eksekutif | O13: liteEventCopy › reportFull.includes.1
A14: 10 | B14: Not linked · /parkwayshenton/report-full | D14: What's included 3 of 3 | F14: Review & recommendations with a full in-depth report | G14: 完整深度报告，附解读与建议 | H14: Ulasan & saranan dengan laporan mendalam yang penuh | O14: liteEventCopy › reportFull.includes.2
A15: 11 | B15: Not linked · /parkwayshenton/report-full | C15: Offer card | D15: eyebrow | F15: Special offer | G15: 专属优惠 | H15: Tawaran istimewa | O15: liteEventCopy › offer.eyebrow
A16: 12 | B16: Not linked · /parkwayshenton/report-full | C16: Offer card | D16: title | F16: World Alzheimer's Month | G16: 世界阿尔茨海默病月 | H16: Bulan Alzheimer Sedunia | O16: liteEventCopy › offer.title
A17: 13 | B17: Not linked · /parkwayshenton/report-full | C17: Offer card | D17: window | F17: 1 – 30 September 2026 | G17: 2026 年 9 月 1 日 – 30 日 | H17: 1 – 30 September 2026 | O17: liteEventCopy › offer.window
A18: 14 | B18: Not linked · /parkwayshenton/report-full | C18: Offer card | D18: productName | F18: BrainScan Cognitive Test | G18: BrainScan 认知测试 | H18: Ujian Kognitif BrainScan | O18: liteEventCopy › offer.productName
A19: 15 | B19: Not linked · /parkwayshenton/report-full | C19: Offer card | D19: productSub | F19: 4 cognitive domains | G19: 4 大认知领域 | H19: 4 domain kognitif | O19: liteEventCopy › offer.productSub
A20: 16 | B20: Not linked · /parkwayshenton/report-full | C20: Offer card | D20: Domain 1 of 4 | F20: Processing Speed | G20: 处理速度 | H20: Kelajuan Pemprosesan | O20: liteEventCopy › offer.domains.0
A21: 17 | B21: Not linked · /parkwayshenton/report-full | C21: Offer card | D21: Domain 2 of 4 | F21: Executive Function | G21: 执行功能 | H21: Fungsi Eksekutif | O21: liteEventCopy › offer.domains.1
A22: 18 | B22: Not linked · /parkwayshenton/report-full | C22: Offer card | D22: Domain 3 of 4 | F22: Memory | G22: 记忆 | H22: Memori | O22: liteEventCopy › offer.domains.2
A23: 19 | B23: Not linked · /parkwayshenton/report-full | C23: Offer card | D23: Domain 4 of 4 | F23: Attention | G23: 注意力 | H23: Perhatian | O23: liteEventCopy › offer.domains.3
A24: 20 | B24: Not linked · /parkwayshenton/report-full | C24: Offer card | D24: normalPrice | F24: Normal price | G24: 原价 | H24: Harga biasa | O24: liteEventCopy › offer.normalPrice
A25: 21 | B25: Not linked · /parkwayshenton/report-full | C25: Offer card | D25: discountLabel | F25: Alzheimer's Month discount | G25: 阿尔茨海默病月折扣 | H25: Diskaun Bulan Alzheimer | O25: liteEventCopy › offer.discountLabel
A26: 22 | B26: Not linked · /parkwayshenton/report-full | C26: Offer card | D26: total | F26: Total | G26: 总计 | H26: Jumlah | O26: liteEventCopy › offer.total
... A40: 36 | B40: Not linked · /parkwayshenton/report-full | C40: FAQ | D40: Answer 5 | F40: Download your offer proof and show it at the front desk to claim the discounted assessment. The test itself runs in a browser and takes about ten minutes. | G40: 下载您的优惠凭证，在前台出示即可享受折扣评估。测试本身在浏览器中进行，约需十分钟。 | H40: Muat turun bukti tawaran anda dan tunjukkannya di kaunter depan untuk menebus penilaian berdiskaun. Ujian itu sendiri berjalan dalam pelayar dan mengambil masa kira-kira sepuluh minit. | O40: liteEventCopy › reportFull.faqs.4.a
A41: 37 | B41: Not linked · /parkwayshenton/report-full | D41: Disclaimer | F41: This report is intended for wellness screening and educational purposes only. It does not diagnose medical disease or replace professional medical evaluation. Findings should be interpreted together with clinical consultation, lifestyle assessment, and where appropriate, biomedical evaluation. | G41: 本报告仅供健康筛查与科普用途，不构成疾病诊断，也不能取代专业医疗评估。结果应结合临床问诊、生活方式评估，并在必要时结合生理医学检查一并解读。 | H41: Laporan ini bertujuan untuk pemeriksaan kesejahteraan dan pendidikan sahaja. Ia tidak mendiagnosis penyakit perubatan atau menggantikan penilaian perubatan profesional. Penemuan harus ditafsirkan bersama konsultasi klinikal, penilaian gaya hidup dan, jika bersesuaian, penilaian bioperubatan. | O41: liteEventCopy › reportFull.disclaimer
